F
======================================================================
FAIL: test_get_cached_contents_locally (test_unit.download.test_cache.TestGetCachedContentsLocally)
----------------------------------------------------------------------
Traceback (most recent call last):
  File "/usr/lib/python3.6/unittest/mock.py", line 1183, in patched
    return func(*args, **keywargs)
  File "/mnt/d/0/scp_ebook/scp_epub/scp_epub/test_unit/download/test_cache.py", line 23, in test_get_cached_contents_locally
    mock_retrieve_from_local_cache.assert_called_once_with(expected_relative_path, expected_item, expected_filetype)
  File "/usr/lib/python3.6/unittest/mock.py", line 824, in assert_called_once_with
    raise AssertionError(msg)
AssertionError: Expected 'retrieve_from_local_cache' to be called once. Called 0 times.

----------------------------------------------------------------------
Ran 1 test in 0.001s

FAILED (failures=1)
